<?xml version="1.0"?>
<robot  xmlns:xacro="http://www.ros.org/wiki/xacro">
  <xacro:include filename="$(find robotv1_description)/urdf/utilities.xacro"/>
  <xacro:property name="lenx_gri" value="0.06"/>
  <xacro:property name="leny_gri" value="0.03"/>
  <xacro:property name="lenz_gri" value="0.04"/>

  <xacro:macro name="gripper" params="prefix">
    <link name="${prefix}_gripper">
      <visual>
        <geometry>
          <box size="${lenx_gri} ${leny_gri} ${lenz_gri}"/>
        </geometry>
      <origin rpy="0 0 0 " xyz="0.0 0 0"/>
      <material name="black"/>
      </visual>
      <inertial>
        <mass value=".001"/>
        <inertia
          ixx="0.001" ixy="0.0" ixz="0.0"
          iyy="0.001" iyz="0.0"
          izz="0.001"/>
      </inertial>
    </link>

    <joint name="${prefix}_left_finger_joint" type="revolute">
      <origin rpy="0 ${-pi/2} 0" xyz="0.0 0.01 0"/>
      <parent link="${prefix}_gripper"/>
      <child link="${prefix}_left_finger"/>
      <axis xyz="0 0 1"/>
      <limit lower="0" upper="${pi/4}" effort="0.0001" velocity="0.0001"/>
    </joint>

    <link name="${prefix}_left_finger">
      <visual>
      <origin rpy="0 0 0" xyz="0 0 0"/>
        <geometry>
          <mesh filename="package://urdf_tutorial/meshes/l_finger.dae"/>
        </geometry>
      </visual>
      <inertial>
        <mass value="0.0001"/>
        <inertia
          ixx="0.001" ixy="0.0" ixz="0.0"
          iyy="0.001" iyz="0.0"
          izz="0.001"/>
      </inertial>
    </link>

    <joint name="${prefix}_left_tip_joint" type="fixed">
      <parent link="${prefix}_left_finger"/>
      <child link="${prefix}_left_tip"/>
    </joint>

    <link name="${prefix}_left_tip">
      <visual>
        <origin rpy="0.0 0 0" xyz="0.09137 0.00495 0"/>
        <geometry>
          <mesh filename="package://urdf_tutorial/meshes/l_finger_tip.dae"/>
        </geometry>
      </visual>
      <inertial>
        <mass value="0.0001"/>
        <inertia
          ixx="0.001" ixy="0.0" ixz="0.0"
          iyy="0.001" iyz="0.0"
          izz="0.001"/>
      </inertial>
    </link>

    <joint name="${prefix}_right_finger_joint" type="revolute">
      <origin rpy="0 ${-pi/2} 0" xyz="0.0 -0.01 0"/>
      <parent link="${prefix}_gripper"/>
      <child link="${prefix}_right_finger"/>
      <axis xyz="0 0 1"/>
      <limit lower="${-pi/4}" upper="0" effort="0.0001" velocity="0.0001"/>
    </joint>

    <link name="${prefix}_right_finger">
    <visual>
      <origin rpy="-3.1415 0 0" xyz="0 0 0"/>
      <geometry>
        <mesh filename="package://urdf_tutorial/meshes/l_finger.dae"/>
      </geometry>
    </visual>
      <inertial>
        <mass value="0.0001"/>
        <inertia
          ixx="0.001" ixy="0.0" ixz="0.0"
          iyy="0.001" iyz="0.0"
          izz="0.001"/>
      </inertial>
    </link>

    <joint name="${prefix}_right_tip_joint" type="fixed">
      <parent link="${prefix}_right_finger"/>
      <child link="${prefix}_right_tip"/>
    </joint>

    <link name="${prefix}_right_tip">
      <visual>
      <origin rpy="-3.1415 0 0" xyz="0.09137 0.00495 0"/>
        <geometry>
          <mesh filename="package://urdf_tutorial/meshes/l_finger_tip.dae"/>
        </geometry>
      </visual>
      <inertial>
        <mass value="0.0001"/>
        <inertia
          ixx="0.001" ixy="0.0" ixz="0.0"
          iyy="0.001" iyz="0.0"
          izz="0.001"/>
      </inertial>
    </link>

  <transmission name="${prefix}_left_finger_joint_tran">
    <type> transmission_interface/SimpleTransmission</type>
    <joint name="${prefix}_left_finger_joint">
      <hardwareInterface>hardware_interface/EffortJointInterface</hardwareInterface>
    </joint>
    <actuator name="${prefix}_left_finger_joint_motor">
      <hardwareInterface>hardware_interface/EffortJointInterface</hardwareInterface>
      <mechanicalReduction>1</mechanicalReduction>
    </actuator>
  </transmission>
  
  <transmission name="${prefix}_right_finger_joint_tran">
    <type> transmission_interface/SimpleTransmission</type>
    <joint name="${prefix}_right_finger_joint">
      <hardwareInterface>hardware_interface/EffortJointInterface</hardwareInterface>
    </joint>
    <actuator name="${prefix}_right_finger_joint_motor">
      <hardwareInterface>hardware_interface/EffortJointInterface</hardwareInterface>
      <mechanicalReduction>1</mechanicalReduction>
    </actuator>
  </transmission>


  </xacro:macro>
</robot>
