<?xml version="1.0" ?>
<!-- =================================================================================== -->
<!-- |    This document was autogenerated by xacro from robotv1.xacro                  | -->
<!-- |    EDITING THIS FILE BY HAND IS NOT RECOMMENDED                                 | -->
<!-- =================================================================================== -->
<robot name="robotv1" xmlns:xacro="http://www.ros.org/wiki/xacro">
  <!--Constant for the robotv1-->
  <link name="pelvis">
    <visual>
      <origin rpy="0 0 0" xyz="0 0 0 "/>
      <geometry>
        <box size="0.08 0.16 0.06"/>
      </geometry>
      <material name="white"/>
    </visual>
    <inertial>
      <mass value="2.0736"/>
      <inertia ixx="0.504576" ixy="0.0" ixz="0.0" iyy="0.504576" iyz="0.0" izz="0.504576"/>
    </inertial>
    <collision>
      <origin rpy="0 0 0" xyz="0 0 0 "/>
      <geometry>
        <box size="0.08 0.16 0.06"/>
      </geometry>
    </collision>
  </link>
  <gazebo reference="pelvis">
    <mu1>0.2</mu1>
    <mu2>0.2</mu2>
    <material>Gazebo/White</material>
  </gazebo>
  <material name="black">
    <color rgba="0.0 0.0 0.0 1.0"/>
  </material>
  <material name="blue">
    <color rgba="0.0 0.0 0.8 1.0"/>
  </material>
  <material name="green">
    <color rgba="0.0 0.8 0.0 1.0"/>
  </material>
  <material name="grey">
    <color rgba="0.2 0.2 0.2 1.0"/>
  </material>
  <material name="orange">
    <color rgba="1.0 0.423529411765 0.0392156862745 1.0"/>
  </material>
  <material name="brown">
    <color rgba="0.870588235294 0.811764705882 0.764705882353 1.0"/>
  </material>
  <material name="red">
    <color rgba="0.8 0.0 0.0 1.0"/>
  </material>
  <material name="white">
    <color rgba="1.0 1.0 1.0 1.0"/>
  </material>
  <!-- ros_control plugin -->
  <gazebo>
    <plugin filename="libgazebo_ros_control.so" name="gazebo_ros_control">
      <robotNamespace>/robotv1</robotNamespace>
      <robotSimType>gazebo_ros_control/DefaultRobotHWSim</robotSimType>
      <legacyModeNS>true</legacyModeNS>
    </plugin>
  </gazebo>
  <link name="dummy"/>
  <joint name="dummy_to_pelvis" type="fixed">
    <origin rpy="0 0 0" xyz="0 0 0.5"/>
    <parent link="dummy"/>
    <child link="pelvis"/>
  </joint>
  <joint name="right_leg_hip_1_joint" type="revolute">
    <parent link="pelvis"/>
    <child link="right_leg_hip_2"/>
    <origin xyz="0 -0.08 0"/>
    <axis xyz="0 1 0"/>
    <dynamics damping="0.7"/>
    <limit effort="2" lower="-1.57079632679" upper="1.57079632679" velocity="1.0"/>
  </joint>
  <link name="right_leg_hip_2">
    <visual>
      <origin rpy="0 0 0" xyz="0 -0.015 0"/>
      <geometry>
        <box size="0.04 0.03 0.06"/>
      </geometry>
      <material name="black"/>
    </visual>
    <inertial>
      <mass value="0.1944"/>
      <inertia ixx="0.00729" ixy="0.0" ixz="0.0" iyy="0.00729" iyz="0.0" izz="0.00729"/>
    </inertial>
    <collision>
      <origin rpy="0 0 0" xyz="0 -0.015 0"/>
      <geometry>
        <box size="0.04 0.03 0.06"/>
      </geometry>
    </collision>
  </link>
  <joint name="right_leg_hip_2_joint" type="revolute">
    <parent link="right_leg_hip_2"/>
    <child link="right_leg_hip_3"/>
    <origin xyz="0 -0.03 0"/>
    <axis xyz="1 0 0"/>
    <dynamics damping="0.7"/>
    <limit effort="2" lower="-1.57079632679" upper="1.57079632679" velocity="1.0"/>
  </joint>
  <link name="right_leg_hip_3">
    <visual>
      <origin rpy="0 0 0" xyz="0 0 -0.045"/>
      <geometry>
        <box size="0.07 0.03 0.09"/>
      </geometry>
      <material name="orange"/>
    </visual>
    <inertial>
      <mass value="0.5103"/>
      <inertia ixx="0.0382725" ixy="0.0" ixz="0.0" iyy="0.0382725" iyz="0.0" izz="0.0382725"/>
    </inertial>
    <collision>
      <origin rpy="0 0 0" xyz="0 0 -0.045"/>
      <geometry>
        <box size="0.07 0.03 0.09"/>
      </geometry>
    </collision>
  </link>
  <joint name="right_leg_hip_3_joint" type="revolute">
    <parent link="right_leg_hip_3"/>
    <child link="right_leg_upp_leg"/>
    <origin xyz="0 0 -0.09"/>
    <axis xyz="0 0 1"/>
    <dynamics damping="0.7"/>
    <limit effort="2" lower="-1.57079632679" upper="1.57079632679" velocity="1.0"/>
  </joint>
  <link name="right_leg_upp_leg">
    <visual>
      <origin rpy="0 0 0" xyz="0 0 -0.03"/>
      <geometry>
        <box size="0.03 0.04 0.06"/>
      </geometry>
      <material name="black"/>
    </visual>
    <inertial>
      <mass value="0.1944"/>
      <inertia ixx="0.008424" ixy="0.0" ixz="0.0" iyy="0.008424" iyz="0.0" izz="0.008424"/>
    </inertial>
    <collision>
      <origin rpy="0 0 0" xyz="0 0 -0.03"/>
      <geometry>
        <box size="0.03 0.04 0.06"/>
      </geometry>
    </collision>
  </link>
  <joint name="right_leg_knee_joint" type="revolute">
    <parent link="right_leg_upp_leg"/>
    <child link="right_leg_low_leg"/>
    <origin xyz="0 0 -0.06"/>
    <axis xyz="0 1 0"/>
    <dynamics damping="0.7"/>
    <limit effort="2" lower="0" upper="2.74889357189" velocity="1.0"/>
  </joint>
  <link name="right_leg_low_leg">
    <visual>
      <origin rpy="0 0 0" xyz="0 0 -0.065"/>
      <geometry>
        <box size="0.02 0.02 0.13"/>
      </geometry>
      <material name="orange"/>
    </visual>
    <inertial>
      <mass value="0.1404"/>
      <inertia ixx="0.020241" ixy="0.0" ixz="0.0" iyy="0.020241" iyz="0.0" izz="0.020241"/>
    </inertial>
    <collision>
      <origin rpy="0 0 0" xyz="0 0 -0.065"/>
      <geometry>
        <box size="0.02 0.02 0.13"/>
      </geometry>
    </collision>
  </link>
  <joint name="right_leg_ang_1_joint" type="revolute">
    <parent link="right_leg_low_leg"/>
    <child link="right_leg_ang_1"/>
    <origin rpy="0 0 0" xyz="0 0 -0.1"/>
    <axis xyz="1 0 0"/>
    <dynamics damping="0.7"/>
    <limit effort="2" lower="-0.785398163397" upper="0.785398163397" velocity="1.0"/>
  </joint>
  <link name="right_leg_ang_1">
    <visual>
      <origin rpy="0 0 0" xyz="0 0 0"/>
      <geometry>
        <box size="0.04 0.03 0.06"/>
      </geometry>
      <material name="black"/>
    </visual>
    <inertial>
      <mass value="0.1944"/>
      <inertia ixx="0.00729" ixy="0.0" ixz="0.0" iyy="0.00729" iyz="0.0" izz="0.00729"/>
    </inertial>
    <collision>
      <origin rpy="0 0 0" xyz="0 0 0"/>
      <geometry>
        <box size="0.04 0.03 0.06"/>
      </geometry>
    </collision>
  </link>
  <joint name="right_leg_ang_2_joint" type="revolute">
    <parent link="right_leg_ang_1"/>
    <child link="right_leg_ang_2"/>
    <origin xyz="-0.02 0 0"/>
    <axis xyz="0 1 0"/>
    <dynamics damping="0.7"/>
    <limit effort="2" lower="-0.785398163397" upper="0.785398163397" velocity="1.0"/>
  </joint>
  <link name="right_leg_ang_2">
    <visual>
      <origin rpy="0 0 0" xyz="0 0 -0.03"/>
      <geometry>
        <box size="0.03 0.04 0.06"/>
      </geometry>
      <material name="orange"/>
    </visual>
    <inertial>
      <mass value="0.1944"/>
      <inertia ixx="0.008424" ixy="0.0" ixz="0.0" iyy="0.008424" iyz="0.0" izz="0.008424"/>
    </inertial>
    <collision>
      <origin rpy="0 0 0" xyz="-0.04 0 -0.03"/>
      <geometry>
        <box size="0.03 0.04 0.06"/>
      </geometry>
    </collision>
  </link>
  <joint name="right_leg_foot_joint" type="fixed">
    <parent link="right_leg_ang_2"/>
    <child link="right_leg_foot"/>
    <origin xyz="0 0 -0.06"/>
  </joint>
  <link name="right_leg_foot">
    <visual>
      <origin rpy="0 0 0" xyz="0.035 0 -0.001"/>
      <geometry>
        <box size="0.1 0.04 0.002"/>
      </geometry>
      <material name="orange"/>
    </visual>
    <inertial>
      <mass value="0.0216"/>
      <inertia ixx="0.00028872" ixy="0.0" ixz="0.0" iyy="0.00028872" iyz="0.0" izz="0.00028872"/>
    </inertial>
    <collision>
      <origin rpy="0 0 0" xyz="0.035 0 -0.001"/>
      <geometry>
        <box size="0.1 0.04 0.002"/>
      </geometry>
    </collision>
  </link>
  <transmission name="right_leg_hip_1_tran">
    <type>transmission_interface/SimpleTransmission</type>
    <joint name="right_leg_hip_1_joint">
      <hardwareInterface>hardware_interface/EffortJointInterface</hardwareInterface>
    </joint>
    <actuator name="right_leg_hip_1_motor">
      <hardwareInterface>hardware_interface/EffortJointInterface</hardwareInterface>
      <mechanicalReduction>1</mechanicalReduction>
    </actuator>
  </transmission>
  <transmission name="right_leg_hip_2_tran">
    <type>transmission_interface/SimpleTransmission</type>
    <joint name="right_leg_hip_2_joint">
      <hardwareInterface>hardware_interface/EffortJointInterface</hardwareInterface>
    </joint>
    <actuator name="right_leg_hip_2_motor">
      <hardwareInterface>hardware_interface/EffortJointInterface</hardwareInterface>
      <mechanicalReduction>1</mechanicalReduction>
    </actuator>
  </transmission>
  <transmission name="right_leg_hip_3_tran">
    <type>transmission_interface/SimpleTransmission</type>
    <joint name="right_leg_hip_3_joint">
      <hardwareInterface>hardware_interface/EffortJointInterface</hardwareInterface>
    </joint>
    <actuator name="right_leg_hip_3_motor">
      <hardwareInterface>hardware_interface/EffortJointInterface</hardwareInterface>
      <mechanicalReduction>1</mechanicalReduction>
    </actuator>
  </transmission>
  <transmission name="right_leg_knee_tran">
    <type>transmission_interface/SimpleTransmission</type>
    <joint name="right_leg_knee_joint">
      <hardwareInterface>hardware_interface/EffortJointInterface</hardwareInterface>
    </joint>
    <actuator name="right_leg_knee_motor">
      <hardwareInterface>hardware_interface/EffortJointInterface</hardwareInterface>
      <mechanicalReduction>1</mechanicalReduction>
    </actuator>
  </transmission>
  <transmission name="right_leg_ang_1_tran">
    <type>transmission_interface/SimpleTransmission</type>
    <joint name="right_leg_ang_1_joint">
      <hardwareInterface>hardware_interface/EffortJointInterface</hardwareInterface>
    </joint>
    <actuator name="right_leg_ang_1_motor">
      <hardwareInterface>hardware_interface/EffortJointInterface</hardwareInterface>
      <mechanicalReduction>1</mechanicalReduction>
    </actuator>
  </transmission>
  <transmission name="right_leg_ang_2_tran">
    <type>transmission_interface/SimpleTransmission</type>
    <joint name="right_leg_ang_2_joint">
      <hardwareInterface>hardware_interface/EffortJointInterface</hardwareInterface>
    </joint>
    <actuator name="right_leg_ang_2_motor">
      <hardwareInterface>hardware_interface/EffortJointInterface</hardwareInterface>
      <mechanicalReduction>1</mechanicalReduction>
    </actuator>
  </transmission>
  <!-- Link1 -->
  <gazebo reference="right_leg_hip_2">
    <material>Gazebo/Black</material>
  </gazebo>
  <gazebo reference="right_leg_hip_3">
    <mu1>0.2</mu1>
    <mu2>0.2</mu2>
    <material>Gazebo/Orange</material>
  </gazebo>
  <gazebo reference="right_leg_upp_leg">
    <mu1>0.2</mu1>
    <mu2>0.2</mu2>
    <material>Gazebo/Black</material>
  </gazebo>
  <gazebo reference="right_leg_low_leg">
    <mu1>0.2</mu1>
    <mu2>0.2</mu2>
    <material>Gazebo/Orange</material>
  </gazebo>
  <gazebo reference="right_leg_ang_1">
    <mu1>0.2</mu1>
    <mu2>0.2</mu2>
    <material>Gazebo/Black</material>
  </gazebo>
  <gazebo reference="right_leg_ang_2">
    <mu1>0.2</mu1>
    <mu2>0.2</mu2>
    <material>Gazebo/Orange</material>
  </gazebo>
  <gazebo reference="right_leg_foot">
    <mu1>0.4</mu1>
    <mu2>0.4</mu2>
    <material>Gazebo/Orange</material>
  </gazebo>
  <!--<xacro:arm prefix="left_arm" />-->
</robot>

